Workbook

Sheet README
B2: ATELIER NORTH PTE. LTD. | D2: SGD · synthetic data
B3: Synthetic FP&A portfolio model · model guide and conventions
C5: SYNTHETIC DATA | D5: All companies, transactions and financial data in this workbook are fictional and created solely to demonstrate financial-modelling and FP&A capabilities.
D6: Atelier North Pte. Ltd. does not exist. No client, employer, customer or confidential information appears in this file. The methodology, structure and controls reflect the approach used on real engagements; the numbers do not.
B8: MODEL AT A GLANCE
C9: Purpose | D9: A management decision tool for an owner-managed fashion retailer under short-term cash pressure.
C10: Key questions | D10: Will we run out of cash this quarter? Which channels make money? Is the flagship store viable? What should we do?
C11: Business | D11: Atelier North Pte. Ltd. - independent Singapore fashion / apparel retailer, owner-managed, books kept in Xero.
C12: Channels | D12: Flagship store · E-commerce · Events / pop-ups · Consignment partners
C13: Reporting currency | D13: Singapore Dollars (SGD). All lines are stated net of GST; GST is settled quarterly as a single payment.
C14: Historical period | D14: Six months ended 31 July 2026 (Feb-26 to Jul-26) - channel P&L and break-even base.
C15: Forecast period | D15: 13 weeks, Monday 3 August 2026 to Sunday 1 November 2026.
C16: Source data | D16: Xero trial balance and tracking categories, AP ageing and purchase-order commitments, POS and e-commerce reports.
B18: WORKBOOK NAVIGATION
C19: Dashboard | D19: One-page executive summary: eight KPI cards, four headline conclusions and four charts. Start here.
C20: Management Insights | D20: Seven findings, each with its commercial consequence and a recommended action.
C21: 13W Cash Flow | D21: Rolling 13-week forecast. Receipts by channel, outflows by cost line, closing cash against the minimum buffer.
C22: Channel Profitability | D22: Six-month management P&L by channel: contribution margin, then direct channel profit, then shared overhead.
C23: Store Break-Even | D23: Flagship store viability: break-even sales, margin of safety, two sensitivity grids and a driver ranking.
C24: Scenarios | D24: Continue / improve / exit, each with a full 13-week cash rebuild and the thresholds that decide between them.
C25: Assumptions | D25: Every hardcoded input in the model, in sixteen labelled sections. The only sheet you need to edit.
C26: Controls | D26: Thirty reconciliation and integrity checks. MODEL STATUS must read PASS before the pack is issued.
B28: CELL CONVENTIONS
C29: Hardcoded input | D29: Pale yellow fill with navy-blue text. These are the only cells intended to be edited.
C30: Formula | D30: Standard black text - calculated on the same sheet.
C31: Cross-sheet link | D31: Muted green text - pulls a value from another sheet in this workbook.
C32: Key output | D32: Bold navy on a light panel - a headline figure that feeds the Dashboard.
B34: METHODOLOGY AND LIMITATIONS
C35: Cash, not accruals | D35: Receipts run through channel-specific settlement lags; costs run through their actual payment dates. Payment timing is derived from the week dates, so rolling the forecast forward is a one-cell change.
C36: Contribution first | D36: Channels are judged on contribution margin and then on direct channel profit. Shared overhead is held back from the primary view; a fully-absorbed memo view is shown separately.
C37: Break-even | D37: Break-even sales = fixed store costs / contribution margin %, measured after the costs that genuinely move with store sales.
C38: Scenarios | D38: Each scenario rebuilds the weekly cash path from the same drivers. With neutral levers Scenario 1 reproduces the base case exactly - this is tested on the Controls tab.
C39: Limitations | D39: Thirteen weeks only: a liquidity tool, not a budget. No balance sheet or deferred tax. GST is a single quarterly settlement. Exit costs are illustrative estimates.
D41: Prepared as a portfolio work sample. Data synthetic; methodology as used in practice.

Sheet Dashboard
B2: ATELIER NORTH PTE. LTD. | P2: SGD · synthetic data
B3: Management dashboard · 13 weeks from 3 August 2026
B5: CASH POSITION AND RUNWAY
B6: OPENING CASH · WEEK 1 | F6: ENDING CASH · WEEK 13 | J6: LOWEST CASH POINT | N6: CASH RUNWAY
B7: ='13W Cash Flow'!$D$45 -> 205000 | F7: ='13W Cash Flow'!$D$46 -> 139650.22 | J7: ='13W Cash Flow'!$D$51 -> 114528.43 | N7: ='13W Cash Flow'!$D$56 -> 27.780548
B8: Bank balance at 3 August 2026 | F8: ="Net movement "&TEXT('13W Cash Flow'!$D$47,"""S$""#,##0;(""S$""#,##0)")&" over the quarter" -> Net movement (S$65,350) over the quarter | J8: ="Week "&'13W Cash Flow'!$D$52&" · minimum buffer "&TEXT('13W Cash Flow'!$D$41,"""S$""#,##0") -> Week 9 · minimum buffer S$120,000 | N8: To nil cash at the average weekly burn
B10: TRADING AND STORE VIABILITY
B11: NET REVENUE · 13 WEEKS | F11: GROSS MARGIN | J11: STORE PROFIT / (LOSS) PER MONTH | N11: STORE BREAK-EVEN GAP
B12: ='13W Cash Flow'!$Q$77 -> 747630.46 | F12: ='Channel Profitability'!$H$11 -> 0.59786244 | J12: ='Store Break-Even'!$D$28 -> -1104.72 | N12: ='Store Break-Even'!$D$35 -> -2108.2443
B13: Forecast across all four channels | F13: Six months ended 31 July 2026 | J13: After directly attributable fixed costs | N13: ="Break-even "&TEXT('Store Break-Even'!$D$32,"""S$""#,##0")&" per month" -> Break-even S$84,828 per month
B15: WHAT THIS MEANS
B16: ="Cash bottoms out at "&TEXT('13W Cash Flow'!$D$51,"""S$""#,##0")&" in Week "&'13W Cash Flow'!$D$52&IF('13W Cash Flow'!$D$54<0,", which is "&TEXT(-'13W Cash Flow'!$D$54,"""S$""#,##0")&" below the minimum buffer in "&'13W Cash Flow'!$D$55&IF('13W Cash Flow'!$D$55=1," week"," weeks"),", leaving "&TEXT('13W Cash Flow'!$D$54,"""S$""#,##0")&" of headroom")&", before recovering to "&TEXT('13W Cash Flow'!$D$46,"""S$""#,##0")&" by Week 13." -> Cash bottoms out at S$114,528 in Week 9, which is S$5,472 below the minimum buffer in 1 week, before recovering to S$139,650 by Week 13.
B17: ="Inventory and supplier payments take "&TEXT('13W Cash Flow'!$Q$21/'13W Cash Flow'!$Q$36,"0.0%")&" of 13-week outflows "&"("&TEXT('13W Cash Flow'!$Q$21,"""S$""#,##0")&") - the AW26 buy, not trading, is what drains the cash." -> Inventory and supplier payments take 52.5% of 13-week outflows (S$409,023) - the AW26 buy, not trading, is what drains the cash.
B18: ="The flagship store trades "&TEXT(ABS('Store Break-Even'!$D$36),"0.0%")&IF('Store Break-Even'!$D$36<0," below"," above")&" break-even, but earns the highest contribution margin of any channel at "&TEXT('Channel Profitability'!$D$23,"0.0%")&"; e-commerce delivers the largest direct channel profit at "&TEXT('Channel Profitability'!$E$34/6,"""S$""#,##0")&" per month." -> The flagship store trades 2.5% below break-even, but earns the highest contribution margin of any channel at 52.4%; e-commerce delivers the largest direct channel profit at S$28,478 per month.
B19: ="Store improvement ends Week 13 with "&TEXT(Scenarios!$E$63,"""S$""#,##0")&" of cash against "&TEXT(Scenarios!$D$63,"""S$""#,##0")&" as-is and "&TEXT(Scenarios!$F$63,"""S$""#,##0")&" on exit; closure needs "&TEXT(Scenarios!$F$72,"0.0%")&" of store demand to migrate online just to beat standing still." -> Store improvement ends Week 13 with S$163,302 of cash against S$139,650 as-is and S$110,579 on exit; closure needs 3.6% of store demand to migrate online just to beat standing still.
B55: All figures synthetic. Every KPI and chart on this page links directly to the calculation sheets - no dashboard number is keyed independently.
B101: CHART DATA - links to the model; nothing here is keyed independently
B102: Week | C102: Closing cash | D102: Minimum buffer
B103: ="W"&'13W Cash Flow'!D$6 -> W1 | C103: ='13W Cash Flow'!D$40 -> 229516.49 | D103: ='13W Cash Flow'!D$41 -> 120000
B104: ="W"&'13W Cash Flow'!E$6 -> W2 | C104: ='13W Cash Flow'!E$40 -> 210506.61 | D104: ='13W Cash Flow'!E$41 -> 120000
B105: ="W"&'13W Cash Flow'!F$6 -> W3 | C105: ='13W Cash Flow'!F$40 -> 237278.14 | D105: ='13W Cash Flow'!F$41 -> 120000
B106: ="W"&'13W Cash Flow'!G$6 -> W4 | C106: ='13W Cash Flow'!G$40 -> 265003.42 | D106: ='13W Cash Flow'!G$41 -> 120000
B107: ="W"&'13W Cash Flow'!H$6 -> W5 | C107: ='13W Cash Flow'!H$40 -> 173817.29 | D107: ='13W Cash Flow'!H$41 -> 120000
B108: ="W"&'13W Cash Flow'!I$6 -> W6 | C108: ='13W Cash Flow'!I$40 -> 196072.2 | D108: ='13W Cash Flow'!I$41 -> 120000
B109: ="W"&'13W Cash Flow'!J$6 -> W7 | C109: ='13W Cash Flow'!J$40 -> 232293.09 | D109: ='13W Cash Flow'!J$41 -> 120000
B110: ="W"&'13W Cash Flow'!K$6 -> W8 | C110: ='13W Cash Flow'!K$40 -> 180344.9 | D110: ='13W Cash Flow'!K$41 -> 120000
B111: ="W"&'13W Cash Flow'!L$6 -> W9 | C111: ='13W Cash Flow'!L$40 -> 114528.43 | D111: ='13W Cash Flow'!L$41 -> 120000
B112: ="W"&'13W Cash Flow'!M$6 -> W10 | C112: ='13W Cash Flow'!M$40 -> 134028.5 | D112: ='13W Cash Flow'!M$41 -> 120000
B113: ="W"&'13W Cash Flow'!N$6 -> W11 | C113: ='13W Cash Flow'!N$40 -> 129334.06 | D113: ='13W Cash Flow'!N$41 -> 120000
B114: ="W"&'13W Cash Flow'!O$6 -> W12 | C114: ='13W Cash Flow'!O$40 -> 160084.21 | D114: ='13W Cash Flow'!O$41 -> 120000
B115: ="W"&'13W Cash Flow'!P$6 -> W13 | C115: ='13W Cash Flow'!P$40 -> 139650.22 | D115: ='13W Cash Flow'!P$41 -> 120000
B117: Channel | C117: Contribution profit / month | D117: Direct channel profit / month
B118: ='Channel Profitability'!$D$5 -> Physical Store | C118: ='Channel Profitability'!$D$58 -> 43345.28 | D118: ='Channel Profitability'!$D$60 -> -1104.72
B119: ='Channel Profitability'!$E$5 -> E-commerce | C119: ='Channel Profitability'!$E$58 -> 34777.6 | D119: ='Channel Profitability'!$E$60 -> 28477.6
B120: ='Channel Profitability'!$F$5 -> Events / Pop-ups | C120: ='Channel Profitability'!$F$58 -> 12833.1 | D120: ='Channel Profitability'!$F$60 -> 12833.1
B121: ='Channel Profitability'!$G$5 -> Consignment | C121: ='Channel Profitability'!$G$58 -> 9690 | D121: ='Channel Profitability'!$G$60 -> 9690
B123: Flagship store | C123: SGD per month
B124: Current net sales | C124: ='Store Break-Even'!$D$34 -> 82720
B125: Break-even sales | C125: ='Store Break-Even'!$D$32 -> 84828.244
B127: Scenario | C127: Ending cash - Week 13 | D127: Lowest projected cash
...

Sheet Management Insights
B2: ATELIER NORTH PTE. LTD. | D2: SGD · synthetic data
B3: Management summary · findings, consequences and recommended actions | D3: Back to Dashboard
B5: Finding | C5: Why it matters | D5: Recommended action
B6: 1. Cash headroom disappears in Week 9
B7: ="Cash falls from "&TEXT('13W Cash Flow'!$D$45,"""S$""#,##0")&" to "&TEXT('13W Cash Flow'!$D$51,"""S$""#,##0")&" in Week "&'13W Cash Flow'!$D$52&", a shortfall of "&TEXT(-'13W Cash Flow'!$D$54,"""S$""#,##0")&" against the "&TEXT('13W Cash Flow'!$D$41,"""S$""#,##0")&" buffer, before recovering to "&TEXT('13W Cash Flow'!$D$46,"""S$""#,##0")&" by Week 13." -> Cash falls from S$205,000 to S$114,528 in Week 9, a shortfall of S$5,472 against the S$120,000 buffer, before recovering to S$139,650 by Week 13. | C7: The business is not close to running out of cash, but it breaches its own liquidity policy in the week when the AW26 buy, month-end payroll, rent and quarterly GST all land together. One slow trading week or one supplier pulling terms forward turns a policy breach into a funding problem. | D7: Treat Weeks 8-11 as a managed cash window: move to weekly forecast reviews and agree a standby facility of roughly S$75,000 now, while the bank is looking at a profitable trading record.
B9: 2. Inventory timing, not trading, drains the cash
B10: ="Inventory and supplier payments absorb "&TEXT('13W Cash Flow'!$Q$21,"""S$""#,##0")&" of the "&TEXT('13W Cash Flow'!$Q$36,"""S$""#,##0")&" of 13-week outflows ("&TEXT('13W Cash Flow'!$Q$21/'13W Cash Flow'!$Q$36,"0.0%")&"), of which "&TEXT(Assumptions!$C$120,"""S$""#,##0")&" is the scheduled AW26 buy." -> Inventory and supplier payments absorb S$409,023 of the S$779,039 of 13-week outflows (52.5%), of which S$235,000 is the scheduled AW26 buy. | C10: This is a working-capital timing problem wearing the costume of a profitability problem. Cutting operating cost would do far less for cash than moving one payment date, and would damage trading. | D10: Split the Week 8 tranche 60/40 across Weeks 8 and 12, or move the balance to 45-day terms. Re-phasing about S$33,000 keeps every week above the buffer without touching stock intake.
B12: 3. The store trades marginally below break-even
B13: ="Store net sales of "&TEXT('Store Break-Even'!$D$34,"""S$""#,##0")&" per month sit "&TEXT(ABS('Store Break-Even'!$D$36),"0.0%")&" below a break-even of "&TEXT('Store Break-Even'!$D$32,"""S$""#,##0")&", a monthly result of "&TEXT('Store Break-Even'!$D$28,"""S$""#,##0;(""S$""#,##0)")&"." -> Store net sales of S$82,720 per month sit 2.5% below a break-even of S$84,828, a monthly result of (S$1,105). | C13: ="The store is a rounding error away from covering its own costs. The driver ranking shows sales and gross margin move store profit roughly "&TEXT(MIN('Store Break-Even'!$G$66,'Store Break-Even'!$G$67)/MAX('Store Break-Even'!$G$68,'Store Break-Even'!$G$69),"0.0")&" to "&TEXT(MAX('Store Break-Even'!$G$66,'Store Break-Even'!$G$67)/MIN('Store Break-Even'!$G$68,'Store Break-Even'!$G$69),"0.0")&" times as hard as a proportionate move in rent or payroll, so this is a trading question, not a cost-cutting question." -> The store is a rounding error away from covering its own costs. The driver ranking shows sales and gross margin move store profit roughly 2.0 to 2.6 times as hard as a proportionate move in rent or payroll, so this is a trading question, not a cost-cutting question. | D13: ="Set a time-boxed trading threshold rather than debating closure: the store must reach "&TEXT('Store Break-Even'!$D$32,"""S$""#,##0")&" of monthly net sales within two quarters. Track it monthly and decide on evidence at the lease break." -> Set a time-boxed trading threshold rather than debating closure: the store must reach S$84,828 of monthly net sales within two quarters. Track it monthly and decide on evidence at the lease break.
B15: 4. Best margin per sale, worst fixed-cost recovery
B16: ="The store returns the highest contribution margin of any channel at "&TEXT('Channel Profitability'!$D$23,"0.0%")&" against e-commerce at "&TEXT('Channel Profitability'!$E$23,"0.0%")&", yet after direct fixed costs e-commerce earns "&TEXT('Channel Profitability'!$E$34/6,"""S$""#,##0")&" a month and the store "&TEXT('Channel Profitability'!$D$34/6,"""S$""#,##0;(""S$""#,##0)")&"." -> The store returns the highest contribution margin of any channel at 52.4% against e-commerce at 41.6%, yet after direct fixed costs e-commerce earns S$28,478 a month and the store (S$1,105). | C16: Judging channels on gross margin alone would keep the store and starve e-commerce. The store's problem is the rent and base payroll it must clear before the first sale counts. | D16: Judge channels on direct channel profit, not gross margin, and keep shared overhead unallocated in the management pack. Fund e-commerce while marginal contribution exceeds marginal media cost.
B18: 5. Consignment: lowest realised margin, slowest cash
B19: ="Consignment turns a "&TEXT('Channel Profitability'!$G$11,"0.0%")&" product gross margin into a "&TEXT('Channel Profitability'!$G$23,"0.0%")&" contribution margin after a "&TEXT(Assumptions!$C$42,"0.0%")&" partner commission, and the cash arrives "&Assumptions!$C$70&" weeks after the sale." -> Consignment turns a 60.0% product gross margin into a 28.5% contribution margin after a 30.0% partner commission, and the cash arrives 4 weeks after the sale. | C19: Consignment is a distribution channel and an interest-free loan to the partner at the same time. It earns real contribution and needs no fixed cost, so it should not be cut - but it is the worst channel to grow while cash is tight. | D19: Hold consignment at its current scale through the AW26 window. At contract review push for fortnightly remittance or a commission step-down above an agreed monthly volume.
B21: 6. Events are the best margin but cannot be relied on
B22: ="Events return the highest gross margin in the business at "&TEXT('Channel Profitability'!$F$11,"0.0%")&" and a "&TEXT('Channel Profitability'!$F$23,"0.0%")&" contribution margin with no fixed cost, on "&TEXT('Channel Profitability'!$F$8/6,"""S$""#,##0")&" of net revenue per month - but nil in two of the six historical months." -> Events return the highest gross margin in the business at 64.0% and a 44.1% contribution margin with no fixed cost, on S$29,100 of net revenue per month - but nil in two of the six historical months. | C22: Events flatter the average and hide the variance. They cannot replace recurring store or online revenue, and building a fixed-cost base on them would turn a tight quarter into a bad one. | D22: Contract four to six pop-ups per quarter a quarter ahead so the forecast carries real dates. Model them conservatively and treat any upside as cash buffer, not budget.
B24: 7. Improve the store; keep exit as the fallback
B25: ="Monthly run-rate operating profit is "&TEXT(Scenarios!$D$50,"""S$""#,##0")&" as-is, "&TEXT(Scenarios!$E$50,"""S$""#,##0")&" under improvement and "&TEXT(Scenarios!$F$50,"""S$""#,##0")&" on exit; Week 13 cash is "&TEXT(Scenarios!$D$63,"""S$""#,##0")&" / "&TEXT(Scenarios!$E$63,"""S$""#,##0")&" / "&TEXT(Scenarios!$F$63,"""S$""#,##0")&"." -> Monthly run-rate operating profit is S$20,196 as-is, S$27,343 under improvement and S$27,088 on exit; Week 13 cash is S$139,650 / S$163,302 / S$110,579. | C25: ="Exit removes a fixed-cost base the store is not covering, but it consumes cash at the worst possible moment: the exit case spends "&TEXT(Scenarios!$F$67,"0")&" of the 13 weeks below the minimum cash buffer and ends the quarter at "&TEXT(Scenarios!$F$63,"""S$""#,##0")&" against "&TEXT(Scenarios!$E$63,"""S$""#,##0")&" under improvement. It also permanently removes about a quarter of group revenue and needs "&TEXT(Scenarios!$F$73,"0.0%")&" online migration merely to match the improvement case - against the "&TEXT(Scenarios!$F$12,"0.0%")&" assumed." -> Exit removes a fixed-cost base the store is not covering, but it consumes cash at the worst possible moment: the exit case spends 6 of the 13 weeks below the minimum cash buffer and ends the quarter at S$110,579 against S$163,302 under improvement. It also permanently removes about a quarter of group revenue and needs 25.8% online migration merely to match the improvement case - against the 25.0% assumed. | D25: Adopt the improvement case for two quarters with its sales and margin targets written into store objectives. Review at the lease break and, if the threshold is missed, execute the exit then - having first run a controlled migration test to replace the 25% assumption with evidence.
B27: Every figure quoted above is a live link to the model - change an assumption and these sentences change with it.

Sheet 13W Cash Flow
B2: ATELIER NORTH PTE. LTD. | R2: SGD · synthetic data
B3: Rolling 13-week cash-flow forecast · week commencing Monday 3 August 2026 | R3: Back to Dashboard
B5: SGD | C5: Timing driver | D5: Week 1 | E5: Week 2 | F5: Week 3 | G5: Week 4 | H5: Week 5 | I5: Week 6 | J5: Week 7 | K5: Week 8 | L5: Week 9 | M5: Week 10 | N5: Week 11 | O5: Week 12 | P5: Week 13 | Q5: 13-Week Total | R5: Weekly Average
B6: Week number | D6: 1 | E6: =D6+1 -> 2 | F6: =E6+1 -> 3 | G6: =F6+1 -> 4 | H6: =G6+1 -> 5 | I6: =H6+1 -> 6 | J6: =I6+1 -> 7 | K6: =J6+1 -> 8 | L6: =K6+1 -> 9 | ... P6: =O6+1 -> 13
B7: Week commencing | D7: =Assumptions!$C$8 -> 46237 | E7: =D7+7 -> 46244 | F7: =E7+7 -> 46251 | G7: =F7+7 -> 46258 | H7: =G7+7 -> 46265 | I7: =H7+7 -> 46272 | J7: =I7+7 -> 46279 | K7: =J7+7 -> 46286 | L7: =K7+7 -> 46293 | ... P7: =O7+7 -> 46321
B8: Week ending | D8: =D7+6 -> 46243 | E8: =E7+6 -> 46250 | F8: =F7+6 -> 46257 | G8: =G7+6 -> 46264 | H8: =H7+6 -> 46271 | I8: =I7+6 -> 46278 | J8: =J7+6 -> 46285 | K8: =K7+6 -> 46292 | ... P8: =P7+6 -> 46327
B10: OPENING CASH | C10: prior week close | D10: =Assumptions!$C$13 -> 205000 | E10: =D40 -> 229516.49 | F10: =E40 -> 210506.61 | G10: =F40 -> 237278.14 | H10: =G40 -> 265003.42 | I10: =H40 -> 173817.29 | J10: =I40 -> 196072.2 | K10: =J40 -> 232293.09 | L10: =K40 -> 180344.9 | ... P10: =O40 -> 160084.21
B12: CASH RECEIPTS
B13: Physical store receipts | C13: 92% same week | D13: =D73*Assumptions!$C$67+IF(D$6=1,Assumptions!$C$72,INDEX($D$73:$P$73,1,D$6-1)*(1-Assumptions!$C$67)) -> 18197.668 | E13: =E73*Assumptions!$C$67+IF(E$6=1,Assumptions!$C$72,INDEX($D$73:$P$73,1,E$6-1)*(1-Assumptions!$C$67)) -> 20410.107 | F13: =F73*Assumptions!$C$67+IF(F$6=1,Assumptions!$C$72,INDEX($D$73:$P$73,1,F$6-1)*(1-Assumptions!$C$67)) -> 17799.69 | G13: =G73*Assumptions!$C$67+IF(G$6=1,Assumptions!$C$72,INDEX($D$73:$P$73,1,G$6-1)*(1-Assumptions!$C$67)) -> 17204.331 | H13: =H73*Assumptions!$C$67+IF(H$6=1,Assumptions!$C$72,INDEX($D$73:$P$73,1,H$6-1)*(1-Assumptions!$C$67)) -> 17700.463 | I13: =I73*Assumptions!$C$67+IF(I$6=1,Assumptions!$C$72,INDEX($D$73:$P$73,1,I$6-1)*(1-Assumptions!$C$67)) -> 18448.478 | J13: =J73*Assumptions!$C$67+IF(J$6=1,Assumptions!$C$72,INDEX($D$73:$P$73,1,J$6-1)*(1-Assumptions!$C$67)) -> 19036.203 | K13: =K73*Assumptions!$C$67+IF(K$6=1,Assumptions!$C$72,INDEX($D$73:$P$73,1,K$6-1)*(1-Assumptions!$C$67)) -> 19433.109 | ... P13: =P73*Assumptions!$C$67+IF(P$6=1,Assumptions!$C$72,INDEX($D$73:$P$73,1,P$6-1)*(1-Assumptions!$C$67)) -> 21692.418 | Q13: =SUM(D13:P13) -> 249372.28 | R13: =AVERAGE(D13:P13) -> 19182.483
B14: E-commerce receipts | C14: 85% same week | D14: =D74*Assumptions!$C$68+IF(D$6=1,Assumptions!$C$73,INDEX($D$74:$P$74,1,D$6-1)*(1-Assumptions!$C$68)) -> 21016.22 | E14: =E74*Assumptions!$C$68+IF(E$6=1,Assumptions!$C$73,INDEX($D$74:$P$74,1,E$6-1)*(1-Assumptions!$C$68)) -> 22379.28 | F14: =F74*Assumptions!$C$68+IF(F$6=1,Assumptions!$C$73,INDEX($D$74:$P$74,1,F$6-1)*(1-Assumptions!$C$68)) -> 20988.66 | G14: =G74*Assumptions!$C$68+IF(G$6=1,Assumptions!$C$73,INDEX($D$74:$P$74,1,G$6-1)*(1-Assumptions!$C$68)) -> 20514.34 | H14: =H74*Assumptions!$C$68+IF(H$6=1,Assumptions!$C$73,INDEX($D$74:$P$74,1,H$6-1)*(1-Assumptions!$C$68)) -> 21215.04 | I14: =I74*Assumptions!$C$68+IF(I$6=1,Assumptions!$C$73,INDEX($D$74:$P$74,1,I$6-1)*(1-Assumptions!$C$68)) -> 21894.18 | J14: =J74*Assumptions!$C$68+IF(J$6=1,Assumptions!$C$73,INDEX($D$74:$P$74,1,J$6-1)*(1-Assumptions!$C$68)) -> 22357.72 | K14: =K74*Assumptions!$C$68+IF(K$6=1,Assumptions!$C$73,INDEX($D$74:$P$74,1,K$6-1)*(1-Assumptions!$C$68)) -> 22788.92 | ... P14: =P74*Assumptions!$C$68+IF(P$6=1,Assumptions!$C$73,INDEX($D$74:$P$74,1,P$6-1)*(1-Assumptions!$C$68)) -> 25710.3 | Q14: =SUM(D14:P14) -> 293437.6 | R14: =AVERAGE(D14:P14) -> 22572.123
B15: Events / pop-up receipts | C15: banked at event | D15: =D75*Assumptions!$C$69+IF(D$6=1,0,INDEX($D$75:$P$75,1,D$6-1)*(1-Assumptions!$C$69)) -> 0 | E15: =E75*Assumptions!$C$69+IF(E$6=1,0,INDEX($D$75:$P$75,1,E$6-1)*(1-Assumptions!$C$69)) -> 23280 | F15: =F75*Assumptions!$C$69+IF(F$6=1,0,INDEX($D$75:$P$75,1,F$6-1)*(1-Assumptions!$C$69)) -> 0 | G15: =G75*Assumptions!$C$69+IF(G$6=1,0,INDEX($D$75:$P$75,1,G$6-1)*(1-Assumptions!$C$69)) -> 0 | H15: =H75*Assumptions!$C$69+IF(H$6=1,0,INDEX($D$75:$P$75,1,H$6-1)*(1-Assumptions!$C$69)) -> 0 | I15: =I75*Assumptions!$C$69+IF(I$6=1,0,INDEX($D$75:$P$75,1,I$6-1)*(1-Assumptions!$C$69)) -> 0 | J15: =J75*Assumptions!$C$69+IF(J$6=1,0,INDEX($D$75:$P$75,1,J$6-1)*(1-Assumptions!$C$69)) -> 18624 | K15: =K75*Assumptions!$C$69+IF(K$6=1,0,INDEX($D$75:$P$75,1,K$6-1)*(1-Assumptions!$C$69)) -> 0 | ... P15: =P75*Assumptions!$C$69+IF(P$6=1,0,INDEX($D$75:$P$75,1,P$6-1)*(1-Assumptions!$C$69)) -> 25608 | Q15: =SUM(D15:P15) -> 100104 | R15: =AVERAGE(D15:P15) -> 7700.3077
B16: Consignment receipts (net of partner commission) | C16: 4-week lag | D16: =IF(D$6<=Assumptions!$C$70,Assumptions!$C$74/Assumptions!$C$70,INDEX($D$76:$P$76,1,D$6-Assumptions!$C$70)*(1-Assumptions!$C$42)) -> 5495 | E16: =IF(E$6<=Assumptions!$C$70,Assumptions!$C$74/Assumptions!$C$70,INDEX($D$76:$P$76,1,E$6-Assumptions!$C$70)*(1-Assumptions!$C$42)) -> 5495 | F16: =IF(F$6<=Assumptions!$C$70,Assumptions!$C$74/Assumptions!$C$70,INDEX($D$76:$P$76,1,F$6-Assumptions!$C$70)*(1-Assumptions!$C$42)) -> 5495 | G16: =IF(G$6<=Assumptions!$C$70,Assumptions!$C$74/Assumptions!$C$70,INDEX($D$76:$P$76,1,G$6-Assumptions!$C$70)*(1-Assumptions!$C$42)) -> 5495 | H16: =IF(H$6<=Assumptions!$C$70,Assumptions!$C$74/Assumptions!$C$70,INDEX($D$76:$P$76,1,H$6-Assumptions!$C$70)*(1-Assumptions!$C$42)) -> 5275.2 | I16: =IF(I$6<=Assumptions!$C$70,Assumptions!$C$74/Assumptions!$C$70,INDEX($D$76:$P$76,1,I$6-Assumptions!$C$70)*(1-Assumptions!$C$42)) -> 5495 | J16: =IF(J$6<=Assumptions!$C$70,Assumptions!$C$74/Assumptions!$C$70,INDEX($D$76:$P$76,1,J$6-Assumptions!$C$70)*(1-Assumptions!$C$42)) -> 5220.25 | K16: =IF(K$6<=Assumptions!$C$70,Assumptions!$C$74/Assumptions!$C$70,INDEX($D$76:$P$76,1,K$6-Assumptions!$C$70)*(1-Assumptions!$C$42)) -> 5165.3 | ... P16: =IF(P$6<=Assumptions!$C$70,Assumptions!$C$74/Assumptions!$C$70,INDEX($D$76:$P$76,1,P$6-Assumptions!$C$70)*(1-Assumptions!$C$42)) -> 5549.95 | Q16: =SUM(D16:P16) -> 70775.6 | R16: =AVERAGE(D16:P16) -> 5444.2769
B17: Other / one-off receipts | C17: one-off schedule | D17: =IF(D$6=Assumptions!$C$125,Assumptions!$C$124,0) -> 0 | E17: =IF(E$6=Assumptions!$C$125,Assumptions!$C$124,0) -> 0 | F17: =IF(F$6=Assumptions!$C$125,Assumptions!$C$124,0) -> 0 | G17: =IF(G$6=Assumptions!$C$125,Assumptions!$C$124,0) -> 0 | H17: =IF(H$6=Assumptions!$C$125,Assumptions!$C$124,0) -> 0 | I17: =IF(I$6=Assumptions!$C$125,Assumptions!$C$124,0) -> 0 | J17: =IF(J$6=Assumptions!$C$125,Assumptions!$C$124,0) -> 0 | K17: =IF(K$6=Assumptions!$C$125,Assumptions!$C$124,0) -> 0 | ... P17: =IF(P$6=Assumptions!$C$125,Assumptions!$C$124,0) -> 0 | Q17: =SUM(D17:P17) -> 0 | R17: =AVERAGE(D17:P17) -> 0
B18: Total cash receipts | D18: =SUM(D13:D17) -> 44708.888 | E18: =SUM(E13:E17) -> 71564.387 | F18: =SUM(F13:F17) -> 44283.35 | G18: =SUM(G13:G17) -> 43213.671 | H18: =SUM(H13:H17) -> 44190.703 | I18: =SUM(I13:I17) -> 45837.658 | J18: =SUM(J13:J17) -> 65238.173 | K18: =SUM(K13:K17) -> 47387.329 | ... P18: =SUM(P13:P17) -> 78560.668 | Q18: =SUM(D18:P18) -> 713689.48 | R18: =AVERAGE(D18:P18) -> 54899.191
B20: CASH OUTFLOWS
B21: Inventory and supplier payments | C21: replenish + AW26 buy | D21: =D89 -> 11016.171 | E21: =E89 -> 70954.325 | F21: =F89 -> 10808.488 | G21: =G89 -> 10647.29 | H21: =H89 -> 57041.454 | I21: =I89 -> 11432.082 | J21: =J89 -> 15596.687 | K21: =K89 -> 93919.214 | ... P21: =P89 -> 18688.146 | Q21: =SUM(D21:P21) -> 409023.13 | R21: =AVERAGE(D21:P21) -> 31463.318
B22: Store payroll | C22: month end | D22: =Assumptions!$C$47*D70 -> 0 | E22: =Assumptions!$C$47*E70 -> 0 | F22: =Assumptions!$C$47*F70 -> 0 | G22: =Assumptions!$C$47*G70 -> 0 | H22: =Assumptions!$C$47*H70 -> 18500 | I22: =Assumptions!$C$47*I70 -> 0 | J22: =Assumptions!$C$47*J70 -> 0 | K22: =Assumptions!$C$47*K70 -> 0 | ... P22: =Assumptions!$C$47*P70 -> 18500 | Q22: =SUM(D22:P22) -> 55500 | R22: =AVERAGE(D22:P22) -> 4269.2308
B23: Corporate and admin payroll | C23: month end | D23: =Assumptions!$C$92*D70 -> 0 | E23: =Assumptions!$C$92*E70 -> 0 | F23: =Assumptions!$C$92*F70 -> 0 | G23: =Assumptions!$C$92*G70 -> 0 | H23: =Assumptions!$C$92*H70 -> 26200 | I23: =Assumptions!$C$92*I70 -> 0 | J23: =Assumptions!$C$92*J70 -> 0 | K23: =Assumptions!$C$92*K70 -> 0 | ... P23: =Assumptions!$C$92*P70 -> 26200 | Q23: =SUM(D23:P23) -> 78600 | R23: =AVERAGE(D23:P23) -> 6046.1538
B24: Rent | C24: 1st of month | D24: =Assumptions!$C$46*D65 -> 0 | E24: =Assumptions!$C$46*E65 -> 0 | F24: =Assumptions!$C$46*F65 -> 0 | G24: =Assumptions!$C$46*G65 -> 0 | H24: =Assumptions!$C$46*H65 -> 22000 | I24: =Assumptions!$C$46*I65 -> 0 | J24: =Assumptions!$C$46*J65 -> 0 | K24: =Assumptions!$C$46*K65 -> 0 | ... P24: =Assumptions!$C$46*P65 -> 22000 | Q24: =SUM(D24:P24) -> 66000 | R24: =AVERAGE(D24:P24) -> 5076.9231
B25: Digital and brand marketing | C25: % of e-comm + monthly | D25: =D74*Assumptions!$C$40+Assumptions!$C$62*D67 -> 1882.188 | E25: =E74*Assumptions!$C$40+Assumptions!$C$62*E67 -> 6537.42 | F25: =F74*Assumptions!$C$40+Assumptions!$C$62*F67 -> 1862.784 | G25: =G74*Assumptions!$C$40+Assumptions!$C$62*G67 -> 1843.38 | H25: =H74*Assumptions!$C$40+Assumptions!$C$62*H67 -> 1920.996 | I25: =I74*Assumptions!$C$40+Assumptions!$C$62*I67 -> 6479.208 | J25: =J74*Assumptions!$C$40+Assumptions!$C$62*J67 -> 2018.016 | K25: =K74*Assumptions!$C$40+Assumptions!$C$62*K67 -> 2056.824 | ... P25: =P74*Assumptions!$C$40+Assumptions!$C$62*P67 -> 2328.48 | Q25: =SUM(D25:P25) -> 39967.056 | R25: =AVERAGE(D25:P25) -> 3074.3889
B26: Shipping, fulfilment and handling | C26: % of sales | D26: =D74*Assumptions!$C$39+D76*Assumptions!$C$43 -> 1472.398 | E26: =E74*Assumptions!$C$39+E76*Assumptions!$C$43 -> 1589.22 | F26: =F74*Assumptions!$C$39+F76*Assumptions!$C$43 -> 1457.2065 | G26: =G74*Assumptions!$C$39+G76*Assumptions!$C$43 -> 1442.015 | H26: =H74*Assumptions!$C$39+H76*Assumptions!$C$43 -> 1501.6035 | I26: =I74*Assumptions!$C$39+I76*Assumptions!$C$43 -> 1547.178 | J26: =J74*Assumptions!$C$39+J76*Assumptions!$C$43 -> 1577.561 | K26: =K74*Assumptions!$C$39+K76*Assumptions!$C$43 -> 1606.7665 | ... P26: =P74*Assumptions!$C$39+P76*Assumptions!$C$43 -> 1813.56 | Q26: =SUM(D26:P26) -> 20672.929 | R26: =AVERAGE(D26:P26) -> 1590.2253
B27: Merchant and payment fees | C27: % of sales | D27: =D73*Assumptions!$C$34+D74*Assumptions!$C$35+D75*Assumptions!$C$36 -> 932.785 | E27: =E73*Assumptions!$C$34+E74*Assumptions!$C$35+E75*Assumptions!$C$36 -> 1469.7761 | F27: =F73*Assumptions!$C$34+F74*Assumptions!$C$35+F75*Assumptions!$C$36 -> 916.22832 | G27: =G73*Assumptions!$C$34+G74*Assumptions!$C$35+G75*Assumptions!$C$36 -> 903.1064 | H27: =H73*Assumptions!$C$34+H74*Assumptions!$C$35+H75*Assumptions!$C$36 -> 938.42028 | I27: =I73*Assumptions!$C$34+I74*Assumptions!$C$35+I75*Assumptions!$C$36 -> 970.91652 | J27: =J73*Assumptions!$C$34+J74*Assumptions!$C$35+J75*Assumptions!$C$36 -> 1347.5816 | K27: =K73*Assumptions!$C$34+K74*Assumptions!$C$35+K75*Assumptions!$C$36 -> 1013.0999 | ... P27: =P73*Assumptions!$C$34+P74*Assumptions!$C$35+P75*Assumptions!$C$36 -> 1628.4026 | Q27: =SUM(D27:P27) -> 14922.916 | R27: =AVERAGE(D27:P27) -> 1147.9166
B28: Event costs | C28: % of event sales | D28: =D75*Assumptions!$C$41 -> 0 | E28: =E75*Assumptions!$C$41 -> 4190.4 | F28: =F75*Assumptions!$C$41 -> 0 | G28: =G75*Assumptions!$C$41 -> 0 | H28: =H75*Assumptions!$C$41 -> 0 | I28: =I75*Assumptions!$C$41 -> 0 | J28: =J75*Assumptions!$C$41 -> 3352.32 | K28: =K75*Assumptions!$C$41 -> 0 | ... P28: =P75*Assumptions!$C$41 -> 4609.44 | Q28: =SUM(D28:P28) -> 18018.72 | R28: =AVERAGE(D28:P28) -> 1386.0554
B29: Store variable labour | C29: % of store sales | D29: =D73*Assumptions!$C$37 -> 543.837 | E29: =E73*Assumptions!$C$37 -> 618.2568 | F29: =F73*Assumptions!$C$37 -> 526.6632 | G29: =G73*Assumptions!$C$37 -> 515.214 | H29: =H73*Assumptions!$C$37 -> 532.3878 | I29: =I73*Assumptions!$C$37 -> 555.2862 | J29: =J73*Assumptions!$C$37 -> 572.46 | K29: =K73*Assumptions!$C$37 -> 583.9092 | ... P29: =P73*Assumptions!$C$37 -> 652.6044 | Q29: =SUM(D29:P29) -> 7487.7768 | R29: =AVERAGE(D29:P29) -> 575.98283
B30: Utilities and service charge | C30: 15th | D30: =Assumptions!$C$48*D68 -> 0 | E30: =Assumptions!$C$48*E68 -> 2600 | F30: =Assumptions!$C$48*F68 -> 0 | G30: =Assumptions!$C$48*G68 -> 0 | H30: =Assumptions!$C$48*H68 -> 0 | I30: =Assumptions!$C$48*I68 -> 0 | J30: =Assumptions!$C$48*J68 -> 2600 | K30: =Assumptions!$C$48*K68 -> 0 | ... P30: =Assumptions!$C$48*P68 -> 0 | Q30: =SUM(D30:P30) -> 7800 | R30: =AVERAGE(D30:P30) -> 600
B31: Software and subscriptions | C31: 10th | D31: =Assumptions!$C$93*D67 -> 0 | E31: =Assumptions!$C$93*E67 -> 2450 | F31: =Assumptions!$C$93*F67 -> 0 | G31: =Assumptions!$C$93*G67 -> 0 | H31: =Assumptions!$C$93*H67 -> 0 | I31: =Assumptions!$C$93*I67 -> 2450 | J31: =Assumptions!$C$93*J67 -> 0 | K31: =Assumptions!$C$93*K67 -> 0 | ... P31: =Assumptions!$C$93*P67 -> 0 | Q31: =SUM(D31:P31) -> 7350 | R31: =AVERAGE(D31:P31) -> 565.38462
B32: Professional fees | C32: 20th | D32: =Assumptions!$C$60*D69 -> 0 | E32: =Assumptions!$C$60*E69 -> 0 | F32: =Assumptions!$C$60*F69 -> 1800 | G32: =Assumptions!$C$60*G69 -> 0 | H32: =Assumptions!$C$60*H69 -> 0 | I32: =Assumptions!$C$60*I69 -> 0 | J32: =Assumptions!$C$60*J69 -> 1800 | K32: =Assumptions!$C$60*K69 -> 0 | ... P32: =Assumptions!$C$60*P69 -> 0 | Q32: =SUM(D32:P32) -> 5400 | R32: =AVERAGE(D32:P32) -> 415.38462
B33: GST settlement | C33: quarterly | D33: =IF(D$6=Assumptions!$C$89,Assumptions!$C$88,0) -> 0 | E33: =IF(E$6=Assumptions!$C$89,Assumptions!$C$88,0) -> 0 | F33: =IF(F$6=Assumptions!$C$89,Assumptions!$C$88,0) -> 0 | G33: =IF(G$6=Assumptions!$C$89,Assumptions!$C$88,0) -> 0 | H33: =IF(H$6=Assumptions!$C$89,Assumptions!$C$88,0) -> 0 | I33: =IF(I$6=Assumptions!$C$89,Assumptions!$C$88,0) -> 0 | J33: =IF(J$6=Assumptions!$C$89,Assumptions!$C$88,0) -> 0 | K33: =IF(K$6=Assumptions!$C$89,Assumptions!$C$88,0) -> 0 | ... P33: =IF(P$6=Assumptions!$C$89,Assumptions!$C$88,0) -> 0 | Q33: =SUM(D33:P33) -> 26500 | R33: =AVERAGE(D33:P33) -> 2038.4615
B34: Term loan repayment | C34: 5th | D34: =Assumptions!$C$87*D66 -> 4200 | E34: =Assumptions!$C$87*E66 -> 0 | F34: =Assumptions!$C$87*F66 -> 0 | G34: =Assumptions!$C$87*G66 -> 0 | H34: =Assumptions!$C$87*H66 -> 4200 | I34: =Assumptions!$C$87*I66 -> 0 | J34: =Assumptions!$C$87*J66 -> 0 | K34: =Assumptions!$C$87*K66 -> 0 | ... P34: =Assumptions!$C$87*P66 -> 0 | Q34: =SUM(D34:P34) -> 12600 | R34: =AVERAGE(D34:P34) -> 969.23077
B35: Other operating expenses | C35: monthly + variable | D35: =Assumptions!$C$94*D65+D73*Assumptions!$C$38 -> 145.0232 | E35: =Assumptions!$C$94*E65+E73*Assumptions!$C$38 -> 164.86848 | F35: =Assumptions!$C$94*F65+F73*Assumptions!$C$38 -> 140.44352 | G35: =Assumptions!$C$94*G65+G73*Assumptions!$C$38 -> 137.3904 | H35: =Assumptions!$C$94*H65+H73*Assumptions!$C$38 -> 2541.9701 | I35: =Assumptions!$C$94*I65+I73*Assumptions!$C$38 -> 148.07632 | J35: =Assumptions!$C$94*J65+J73*Assumptions!$C$38 -> 152.656 | K35: =Assumptions!$C$94*K65+K73*Assumptions!$C$38 -> 155.70912 | ... P35: =Assumptions!$C$94*P65+P73*Assumptions!$C$38 -> 2574.0278 | Q35: =SUM(D35:P35) -> 9196.7405 | R35: =AVERAGE(D35:P35) -> 707.44158
B36: Total cash outflows | D36: =SUM(D21:D35) -> 20192.402 | E36: =SUM(E21:E35) -> 90574.267 | F36: =SUM(F21:F35) -> 17511.814 | G36: =SUM(G21:G35) -> 15488.395 | H36: =SUM(H21:H35) -> 135376.83 | I36: =SUM(I21:I35) -> 23582.747 | J36: =SUM(J21:J35) -> 29017.282 | K36: =SUM(K21:K35) -> 99335.523 | ... P36: =SUM(P21:P35) -> 98994.661 | Q36: =SUM(D36:P36) -> 779039.27 | R36: =AVERAGE(D36:P36) -> 59926.097
B38: CASH SUMMARY
B39: Net weekly cash movement | D39: =D18-D36 -> 24516.486 | E39: =E18-E36 -> -19009.879 | F39: =F18-F36 -> 26771.536 | G39: =G18-G36 -> 27725.276 | H39: =H18-H36 -> -91186.128 | I39: =I18-I36 -> 22254.91 | J39: =J18-J36 -> 36220.891 | K39: =K18-K36 -> -51948.194 | ... P39: =P18-P36 -> -20433.993 | Q39: =SUM(D39:P39) -> -65349.783 | R39: =AVERAGE(D39:P39) -> -5026.9064
B40: CLOSING CASH | D40: =D10+D39 -> 229516.49 | E40: =E10+E39 -> 210506.61 | F40: =F10+F39 -> 237278.14 | G40: =G10+G39 -> 265003.42 | H40: =H10+H39 -> 173817.29 | I40: =I10+I39 -> 196072.2 | J40: =J10+J39 -> 232293.09 | K40: =K10+K39 -> 180344.9 | ... P40: =P10+P39 -> 139650.22
B41: Minimum cash threshold | D41: =Assumptions!$C$14 -> 120000 | E41: =Assumptions!$C$14 -> 120000 | F41: =Assumptions!$C$14 -> 120000 | G41: =Assumptions!$C$14 -> 120000 | H41: =Assumptions!$C$14 -> 120000 | I41: =Assumptions!$C$14 -> 120000 | J41: =Assumptions!$C$14 -> 120000 | K41: =Assumptions!$C$14 -> 120000 | ... P41: =Assumptions!$C$14 -> 120000
B42: Headroom / (shortfall) vs threshold | D42: =D40-D41 -> 109516.49 | E42: =E40-E41 -> 90506.607 | F42: =F40-F41 -> 117278.14 | G42: =G40-G41 -> 145003.42 | H42: =H40-H41 -> 53817.29 | I42: =I40-I41 -> 76072.2 | J42: =J40-J41 -> 112293.09 | K42: =K40-K41 -> 60344.898 | ... P42: =P40-P41 -> 19650.217
B44: KEY OUTPUTS - these cells feed the Dashboard
B45: Opening cash - Week 1 | D45: =D10 -> 205000 | F45: Per the Assumptions tab.
B46: Closing cash - Week 13 | D46: =P40 -> 139650.22
B47: Net cash movement over 13 weeks | D47: =P40-D10 -> -65349.783
...

Sheet Scenarios
B2: ATELIER NORTH PTE. LTD. | Q2: SGD · synthetic data
B3: Management scenarios · 13-week cash outcome and monthly run-rate P&L | Q3: Back to Dashboard
B4: ="Preferred scenario: "&INDEX($D$6:$F$6,MATCH(MAX($D$50:$F$50),$D$50:$F$50,0))&" · highest monthly run-rate operating profit at "&TEXT(MAX($D$50:$F$50),"""S$""#,##0")&", the strongest Week 13 cash position at "&TEXT(INDEX($D$63:$F$63,MATCH(MAX($D$50:$F$50),$D$50:$F$50,0)),"""S$""#,##0")&" and "&INDEX($D$67:$F$67,MATCH(MAX($D$50:$F$50),$D$50:$F$50,0))&IF(INDEX($D$67:$F$67,MATCH(MAX($D$50:$F$50),$D$50:$F$50,0))=1," week"," weeks")&" below the minimum cash buffer." -> Preferred scenario: 2. Store Improvement · highest monthly run-rate operating profit at S$27,343, the strongest Week 13 cash position at S$163,302 and 0 weeks below the minimum cash buffer.
B5: SCENARIO LEVERS - the only inputs on this sheet (amber cells)
B6: Lever | D6: 1. Current Operations | E6: 2. Store Improvement | F6: 3. Store Exit / Channel Shift | H6: Note
B7: Store net sales change | D7: 0 | E7: 0.06 | F7: 0 | H7: Improvement case: conversion, clienteling and appointment selling.
B8: Store gross margin change (percentage points) | D8: 0 | E8: 0.015 | F8: 0 | H8: Tighter markdown control and better buy discipline.
B9: Store base payroll change | D9: 0 | E9: -0.12 | F9: 0 | H9: Reduced opening hours on the two quietest trading days.
B10: Store other fixed cost change | D10: 0 | E10: -0.08 | F10: 0 | H10: Utilities, POS and sundry occupancy.
B11: E-commerce sales change (before migration) | D11: 0 | E11: 0.02 | F11: 0
B12: Share of lost store demand migrating to e-commerce | D12: 0 | E12: 0 | F12: 0.25 | H12: Deliberately NOT 100%: walk-in and tourist demand does not follow the brand online.
B13: Digital marketing spend factor | D13: 1 | E13: 1 | F13: 1.3 | H13: Exit case funds paid media to recapture migrating demand.
B14: Store closure effective at the end of week (0 = no closure) | D14: 0 | E14: 0 | F14: 4
B15: One-off exit costs | D15: 0 | E15: 0 | F15: 96000 | H15: Lease break S$33k, reinstatement S$45k, redundancy S$18k.
B16: Share of exit costs settled in the first instalment | D16: 0 | E16: 0 | F16: 0.5
B17: First exit-cost instalment - week | D17: 0 | E17: 0 | F17: 5
B18: Second exit-cost instalment - week | D18: 0 | E18: 0 | F18: 7
B19: Store inventory release - one-off cash inflow | D19: 0 | E19: 0 | F19: 42000 | H19: Clearance of store floor stock.
B20: Week of inventory release | D20: 0 | E20: 0 | F20: 6
B21: Inventory replenishment factor after closure (x base) | D21: 1 | E21: 1 | F21: 0.8 | H21: Smaller forward buy once the store is gone.
B23: MONTHLY RUN-RATE P&L - steady state once each scenario is fully in effect
B24: SGD per month | D24: 1. Current Operations | E24: 2. Store Improvement | F24: 3. Store Exit / Channel Shift | G24: S2 vs S1 | H24: S3 vs S1
B25: Store net sales | D25: ='Channel Profitability'!$D$55*(1+$D$7)*IF($D$14=0,1,0) -> 82720 | E25: ='Channel Profitability'!$D$55*(1+$E$7)*IF($E$14=0,1,0) -> 87683.2 | F25: ='Channel Profitability'!$D$55*(1+$F$7)*IF($F$14=0,1,0) -> 0 | G25: =E25-D25 -> 4963.2 | H25: =F25-D25 -> -82720
B26: E-commerce net sales | D26: ='Channel Profitability'!$E$55*(1+$D$11)+'Channel Profitability'!$D$55*(1-IF($D$14=0,1,0))*$D$12 -> 83600 | E26: ='Channel Profitability'!$E$55*(1+$E$11)+'Channel Profitability'!$D$55*(1-IF($E$14=0,1,0))*$E$12 -> 85272 | F26: ='Channel Profitability'!$E$55*(1+$F$11)+'Channel Profitability'!$D$55*(1-IF($F$14=0,1,0))*$F$12 -> 104280 | G26: =E26-D26 -> 1672 | H26: =F26-D26 -> 20680
B27: Events / pop-up net sales | D27: ='Channel Profitability'!$F$55 -> 29100 | E27: ='Channel Profitability'!$F$55 -> 29100 | F27: ='Channel Profitability'!$F$55 -> 29100 | G27: =E27-D27 -> 0 | H27: =F27-D27 -> 0
B28: Consignment net sales | D28: ='Channel Profitability'!$G$55 -> 34000 | E28: ='Channel Profitability'!$G$55 -> 34000 | F28: ='Channel Profitability'!$G$55 -> 34000 | G28: =E28-D28 -> 0 | H28: =F28-D28 -> 0
B29: NET REVENUE | D29: =SUM(D25:D28) -> 229420 | E29: =SUM(E25:E28) -> 236055.2 | F29: =SUM(F25:F28) -> 167380 | G29: =E29-D29 -> 6635.2 | H29: =F29-D29 -> -62040
B30: Gross profit | D30: =D25*(Assumptions!$C$28+$D$8)+D26*Assumptions!$C$29+D27*Assumptions!$C$30+D28*Assumptions!$C$31 -> 137161.6 | E30: =E25*(Assumptions!$C$28+$E$8)+E26*Assumptions!$C$29+E27*Assumptions!$C$30+E28*Assumptions!$C$31 -> 142358.7 | F30: =F25*(Assumptions!$C$28+$F$8)+F26*Assumptions!$C$29+F27*Assumptions!$C$30+F28*Assumptions!$C$31 -> 101592 | G30: =E30-D30 -> 5197.104 | H30: =F30-D30 -> -35569.6
B31: Gross margin % | D31: =IFERROR(D30/D29,0) -> 0.59786244 | E31: =IFERROR(E30/E29,0) -> 0.60307379 | F31: =IFERROR(F30/F29,0) -> 0.60695424 | G31: =E31-D31 -> 0.0052113538 | H31: =F31-D31 -> 0.0090918002
B33: Contribution margin % - physical store | D33: =Assumptions!$C$28+$D$8-Assumptions!$C$34-Assumptions!$C$37-Assumptions!$C$38 -> 0.524 | E33: =Assumptions!$C$28+$E$8-Assumptions!$C$34-Assumptions!$C$37-Assumptions!$C$38 -> 0.539 | F33: =Assumptions!$C$28+$F$8-Assumptions!$C$34-Assumptions!$C$37-Assumptions!$C$38 -> 0.524
B34: Contribution margin % - e-commerce | D34: =Assumptions!$C$29-Assumptions!$C$35-Assumptions!$C$39-Assumptions!$C$40*$D$13 -> 0.416 | E34: =Assumptions!$C$29-Assumptions!$C$35-Assumptions!$C$39-Assumptions!$C$40*$E$13 -> 0.416 | F34: =Assumptions!$C$29-Assumptions!$C$35-Assumptions!$C$39-Assumptions!$C$40*$F$13 -> 0.389
B35: Contribution margin % - events | D35: =Assumptions!$C$30-Assumptions!$C$36-Assumptions!$C$41 -> 0.441 | E35: =Assumptions!$C$30-Assumptions!$C$36-Assumptions!$C$41 -> 0.441 | F35: =Assumptions!$C$30-Assumptions!$C$36-Assumptions!$C$41 -> 0.441
B36: Contribution margin % - consignment | D36: =Assumptions!$C$31-Assumptions!$C$42-Assumptions!$C$43 -> 0.285 | E36: =Assumptions!$C$31-Assumptions!$C$42-Assumptions!$C$43 -> 0.285 | F36: =Assumptions!$C$31-Assumptions!$C$42-Assumptions!$C$43 -> 0.285
B38: Contribution profit - physical store | D38: =D25*D33 -> 43345.28 | E38: =E25*E33 -> 47261.245 | F38: =F25*F33 -> 0 | G38: =E38-D38 -> 3915.9648 | H38: =F38-D38 -> -43345.28
B39: Contribution profit - e-commerce | D39: =D26*D34 -> 34777.6 | E39: =E26*E34 -> 35473.152 | F39: =F26*F34 -> 40564.92 | G39: =E39-D39 -> 695.552 | H39: =F39-D39 -> 5787.32
B40: Contribution profit - events / pop-ups | D40: =D27*D35 -> 12833.1 | E40: =E27*E35 -> 12833.1 | F40: =F27*F35 -> 12833.1 | G40: =E40-D40 -> 0 | H40: =F40-D40 -> 0
B41: Contribution profit - consignment | D41: =D28*D36 -> 9690 | E41: =E28*E36 -> 9690 | F41: =F28*F36 -> 9690 | G41: =E41-D41 -> 0 | H41: =F41-D41 -> 0
B42: TOTAL CONTRIBUTION PROFIT | D42: =SUM(D38:D41) -> 100645.98 | E42: =SUM(E38:E41) -> 105257.5 | F42: =SUM(F38:F41) -> 63088.02 | G42: =E42-D42 -> 4611.5168 | H42: =F42-D42 -> -37557.96
B43: Contribution margin % | D43: =IFERROR(D42/D29,0) -> 0.4386975 | E43: =IFERROR(E42/E29,0) -> 0.44590205 | F43: =IFERROR(F42/F29,0) -> 0.37691492 | G43: =E43-D43 -> 0.0072045486 | H43: =F43-D43 -> -0.061782574
B45: Direct fixed costs - physical store | D45: =-IF($D$14=0,1,0)*(Assumptions!$C$46+Assumptions!$C$47*(1+$D$9)+(Assumptions!$C$48+Assumptions!$C$49+Assumptions!$C$50)*(1+$D$10)) -> -44450 | E45: =-IF($E$14=0,1,0)*(Assumptions!$C$46+Assumptions!$C$47*(1+$E$9)+(Assumptions!$C$48+Assumptions!$C$49+Assumptions!$C$50)*(1+$E$10)) -> -41914 | F45: =-IF($F$14=0,1,0)*(Assumptions!$C$46+Assumptions!$C$47*(1+$F$9)+(Assumptions!$C$48+Assumptions!$C$49+Assumptions!$C$50)*(1+$F$10)) -> 0 | G45: =E45-D45 -> 2536 | H45: =F45-D45 -> 44450
...

Sheet Channel Profitability
B2: ATELIER NORTH PTE. LTD. | I2: SGD · synthetic data
B3: Management P&L by channel · six months ended 31 July 2026 | I3: Back to Dashboard
B4: Months in period | C4: 6 | E4: Shared overhead is deliberately NOT allocated in the primary view - see the memo section below.
B5: SGD - six months | C5: Rate | D5: Physical Store | E5: E-commerce | F5: Events / Pop-ups | G5: Consignment | H5: Total Business | I5: % of total net revenue
B6: Gross sales | D6: =Assumptions!$J$99 -> 528000 | E6: =Assumptions!$J$100 -> 570000 | F6: =Assumptions!$J$101 -> 180000 | G6: =Assumptions!$J$102 -> 204000 | H6: =SUM(D6:G6) -> 1482000 | I6: =IFERROR(H6/$H$8,0) -> 1.076628
B7: Discounts and returns | D7: =-D6*Assumptions!$C$23 -> -31680 | E7: =-E6*Assumptions!$C$24 -> -68400 | F7: =-F6*Assumptions!$C$25 -> -5400 | G7: =-G6*Assumptions!$C$26 -> 0 | H7: =SUM(D7:G7) -> -105480 | I7: =IFERROR(H7/$H$8,0) -> -0.076628018
B8: Net revenue | D8: =D6+D7 -> 496320 | E8: =E6+E7 -> 501600 | F8: =F6+F7 -> 174600 | G8: =G6+G7 -> 204000 | H8: =SUM(D8:G8) -> 1376520 | I8: =IFERROR(H8/$H$8,0) -> 1
B9: Cost of goods sold | D9: =-D8*(1-Assumptions!$C$28) -> -208454.4 | E9: =-E8*(1-Assumptions!$C$29) -> -200640 | F9: =-F8*(1-Assumptions!$C$30) -> -62856 | G9: =-G8*(1-Assumptions!$C$31) -> -81600 | H9: =SUM(D9:G9) -> -553550.4 | I9: =IFERROR(H9/$H$8,0) -> -0.40213756
B10: Gross profit | D10: =D8+D9 -> 287865.6 | E10: =E8+E9 -> 300960 | F10: =F8+F9 -> 111744 | G10: =G8+G9 -> 122400 | H10: =SUM(D10:G10) -> 822969.6 | I10: =IFERROR(H10/$H$8,0) -> 0.59786244
B11: Gross margin % | D11: =IFERROR(D10/D8,0) -> 0.58 | E11: =IFERROR(E10/E8,0) -> 0.6 | F11: =IFERROR(F10/F8,0) -> 0.64 | G11: =IFERROR(G10/G8,0) -> 0.6 | H11: =IFERROR(H10/H8,0) -> 0.59786244
B13: VARIABLE CHANNEL COSTS (move directly with channel sales)
B14: Payment and merchant fees | D14: =-D8*Assumptions!$C$34 -> -8933.76 | E14: =-E8*Assumptions!$C$35 -> -14546.4 | F14: =-F8*Assumptions!$C$36 -> -3317.4 | H14: =SUM(D14:G14) -> -26797.56
B15: Fulfilment, shipping and handling | E15: =-E8*Assumptions!$C$39 -> -32604 | G15: =-G8*Assumptions!$C$43 -> -3060 | H15: =SUM(D15:G15) -> -35664
B16: Consignment partner commissions | C16: =Assumptions!$C$42 -> 0.3 | G16: =-G8*Assumptions!$C$42 -> -61200 | H16: =SUM(D16:G16) -> -61200
B17: Variable store labour | C17: =Assumptions!$C$37 -> 0.03 | D17: =-D8*Assumptions!$C$37 -> -14889.6 | H17: =SUM(D17:G17) -> -14889.6
B18: Channel marketing (digital performance media) | C18: =Assumptions!$C$40 -> 0.09 | E18: =-E8*Assumptions!$C$40 -> -45144 | H18: =SUM(D18:G18) -> -45144
B19: Event costs (space, fixtures, transport, crew) | C19: =Assumptions!$C$41 -> 0.18 | F19: =-F8*Assumptions!$C$41 -> -31428 | H19: =SUM(D19:G19) -> -31428
B20: Other direct operating costs | C20: =Assumptions!$C$38 -> 0.008 | D20: =-D8*Assumptions!$C$38 -> -3970.56 | H20: =SUM(D20:G20) -> -3970.56
B21: Total variable channel costs | D21: =SUM(D14:D20) -> -27793.92 | E21: =SUM(E14:E20) -> -92294.4 | F21: =SUM(F14:F20) -> -34745.4 | G21: =SUM(G14:G20) -> -64260 | H21: =SUM(D21:G21) -> -219093.72 | I21: =IFERROR(H21/$H$8,0) -> -0.15916494
B22: CONTRIBUTION PROFIT | D22: =D10+D21 -> 260071.68 | E22: =E10+E21 -> 208665.6 | F22: =F10+F21 -> 76998.6 | G22: =G10+G21 -> 58140 | H22: =SUM(D22:G22) -> 603875.88 | I22: =IFERROR(H22/$H$8,0) -> 0.4386975
B23: Contribution margin % | D23: =IFERROR(D22/D8,0) -> 0.524 | E23: =IFERROR(E22/E8,0) -> 0.416 | F23: =IFERROR(F22/F8,0) -> 0.441 | G23: =IFERROR(G22/G8,0) -> 0.285 | H23: =IFERROR(H22/H8,0) -> 0.4386975
B25: DIRECT FIXED COSTS (attributable to a single channel; avoided if that channel closes)
B26: Store rent | D26: =-Assumptions!$C$46*$C$4 -> -132000 | H26: =SUM(D26:G26) -> -132000
B27: Store base payroll | D27: =-Assumptions!$C$47*$C$4 -> -111000 | H27: =SUM(D27:G27) -> -111000
B28: Store utilities and service charge | D28: =-Assumptions!$C$48*$C$4 -> -15600 | H28: =SUM(D28:G28) -> -15600
B29: Store POS and store software | D29: =-Assumptions!$C$49*$C$4 -> -2700 | H29: =SUM(D29:G29) -> -2700
B30: Store insurance and other occupancy | D30: =-Assumptions!$C$50*$C$4 -> -5400 | H30: =SUM(D30:G30) -> -5400
B31: E-commerce platform, apps and subscriptions | E31: =-Assumptions!$C$54*$C$4 -> -6600 | H31: =SUM(D31:G31) -> -6600
B32: E-commerce and fulfilment payroll | E32: =-Assumptions!$C$55*$C$4 -> -31200 | H32: =SUM(D32:G32) -> -31200
B33: Total direct fixed costs | D33: =SUM(D26:D32) -> -266700 | E33: =SUM(E26:E32) -> -37800 | F33: =SUM(F26:F32) -> 0 | G33: =SUM(G26:G32) -> 0 | H33: =SUM(D33:G33) -> -304500 | I33: =IFERROR(H33/$H$8,0) -> -0.22121001
B34: DIRECT CHANNEL PROFIT / (LOSS) | D34: =D22+D33 -> -6628.32 | E34: =E22+E33 -> 170865.6 | F34: =F22+F33 -> 76998.6 | G34: =G22+G33 -> 58140 | H34: =SUM(D34:G34) -> 299375.88 | I34: =IFERROR(H34/$H$8,0) -> 0.21748749
B35: Direct channel margin % | D35: =IFERROR(D34/D8,0) -> -0.013354932 | E35: =IFERROR(E34/E8,0) -> 0.34064115 | F35: =IFERROR(F34/F8,0) -> 0.441 | G35: =IFERROR(G34/G8,0) -> 0.285 | H35: =IFERROR(H34/H8,0) -> 0.21748749
B37: SHARED OVERHEAD (not attributable to a single channel - shown in total only)
B38: Management and admin payroll | H38: =-Assumptions!$C$59*$C$4 -> -126000
B39: Professional fees | H39: =-Assumptions!$C$60*$C$4 -> -10800
B40: General software | H40: =-Assumptions!$C$61*$C$4 -> -5400
B41: Brand marketing (non-channel) | H41: =-Assumptions!$C$62*$C$4 -> -27000
B42: Corporate admin, insurance and bank charges | H42: =-Assumptions!$C$63*$C$4 -> -9000
B43: Total shared overhead | H43: =SUM(H38:H42) -> -178200 | I43: =IFERROR(H43/$H$8,0) -> -0.12945689
B45: OPERATING PROFIT (after shared overhead) | H45: =H34+H43 -> 121175.88 | I45: =IFERROR(H45/$H$8,0) -> 0.088030599
...

Sheet Store Break-Even
B2: ATELIER NORTH PTE. LTD. | I2: SGD · synthetic data
B3: Flagship store viability and break-even analysis · monthly basis | I3: Back to Dashboard
F4: STORE VIABILITY AT A GLANCE
B5: CURRENT STORE TRADING - SGD per month, six-month average to 31 July 2026 | F5: CURRENT NET SALES / MONTH | H5: BREAK-EVEN NET SALES / MONTH
B6: Store net sales | D6: ='Channel Profitability'!$D$55 -> 82720 | F6: =$D$34 -> 82720 | H6: =$D$32 -> 84828.244
B7: Cost of goods sold | D7: ='Channel Profitability'!$D$56 -> -34742.4 | F7: Six-month average | H7: Fixed costs / contribution margin
B8: Gross profit | D8: =D6+D7 -> 47977.6
B9: Gross margin % | D9: =IFERROR(D8/D6,0) -> 0.58 | F9: SALES GAP TO BREAK-EVEN | H9: MARGIN OF SAFETY
F10: =$D$35 -> -2108.2443 | H10: =$D$36 -> -0.025486512
B11: Variable operating costs (move with store sales) | F11: ="or "&TEXT($D$37,"0.0%")&" more sales per month" -> or 2.5% more sales per month | H11: Negative = trading below break-even
B12: Payment and merchant fees | D12: =-D6*Assumptions!$C$34 -> -1488.96
B13: Variable / casual store labour | D13: =-D6*Assumptions!$C$37 -> -2481.6 | F13: CONTRIBUTION MARGIN | H13: STORE PROFIT / (LOSS) PER MONTH
B14: Other direct operating costs | D14: =-D6*Assumptions!$C$38 -> -661.76 | F14: =$D$18 -> 0.524 | H14: =$D$28 -> -1104.72
B15: Total variable operating costs | D15: =SUM(D12:D14) -> -4632.32 | F15: Per S$1 of store net sales | H15: After directly attributable fixed costs
B16: Variable costs as % of net sales | D16: =IFERROR(-D15/D6,0) -> 0.056
B17: CONTRIBUTION PROFIT | D17: =D8+D15 -> 43345.28
B18: Contribution margin % | D18: =IFERROR(D17/D6,0) -> 0.524 | E18: Every S$1 of extra store sales contributes this much toward fixed costs.
B20: Fixed store costs (do not move with sales; avoided only on closure)
B21: Rent | D21: =-Assumptions!$C$46 -> -22000
B22: Base payroll | D22: =-Assumptions!$C$47 -> -18500
B23: Utilities and service charge | D23: =-Assumptions!$C$48 -> -2600
B24: POS and store software | D24: =-Assumptions!$C$49 -> -450
B25: Insurance and other occupancy | D25: =-Assumptions!$C$50 -> -900
B26: Total fixed store costs | D26: =SUM(D21:D25) -> -44450
B28: STORE PROFIT / (LOSS) - per month | D28: =D17+D26 -> -1104.72
B29: Store profit / (loss) - annualised | D29: =D28*12 -> -13256.64
B31: BREAK-EVEN ANALYSIS Break-even sales = fixed store costs / contribution margin %
B32: Break-even net sales - per month | D32: =IFERROR(-D26/D18,0) -> 84828.244
B33: Break-even net sales - per week | D33: =D32/Assumptions!$C$10 -> 19575.749
B34: Current net sales - per month | D34: =D6 -> 82720
B35: Sales above / (below) break-even | D35: =D34-D32 -> -2108.2443
B36: Margin of safety % | D36: =IFERROR(D35/D34,0) -> -0.025486512 | E36: Negative = trading below break-even.
B37: Sales uplift required to break even | D37: =IFERROR(D32/D34-1,0) -> 0.025486512
B38: Sales uplift required to break even - S$ per month | D38: =D32-D34 -> 2108.2443
B39: Alternatively: gross-margin uplift required to break even | D39: =IFERROR(-D26/D6-D18,0) -> 0.013354932 | E39: Percentage points of margin, holding sales flat.
B40: Alternatively: rent reduction required to break even | D40: =IF(D28<0,-D28,0) -> 1104.72 | E40: S$ per month, holding sales and margin flat.
B41: Rent reduction required - % of current rent | D41: =IFERROR(D40/-D21,0) -> 0.050214545
B43: MEMO - cross-check against the 13-week forecast run-rate
B44: Forecast store net sales - 13 weeks | D44: ='13W Cash Flow'!$Q$73 -> 249592.56
B45: Equivalent monthly run-rate | D45: =D44/13*Assumptions!$C$10 -> 83197.52
...

Sheet Assumptions
B2: ATELIER NORTH PTE. LTD. | P2: SGD · synthetic data
B3: Central assumptions · every hardcoded input in the model lives on this sheet | P3: Back to Dashboard
B5: Legend | C5: input | D5: edit these | E5: Black = calculated on this sheet. Green = link to another sheet. Scenario levers are held on the Scenarios tab.
B7: 1. MODEL CONTROL
B8: Week 1 commencing (Monday) | C8: 46237 | D8: date | E8: Roll the forecast by changing this one date.
B9: Historical period ended | C9: 46234 | D9: date | E9: Six months of channel actuals to this date.
B10: Weeks per month conversion factor | C10: 4.3333333 | D10: wks/mth | E10: Used to convert weekly run-rates to monthly.
B12: 2. CASH
B13: Opening cash balance at Week 1 | C13: 205000 | D13: SGD | E13: Bank balance per the Xero bank reconciliation.
B14: Minimum operating cash threshold | C14: 120000 | D14: SGD | E14: ="Board-set buffer: c."&TEXT($C$14/$C$95,"0.0")&" months of total fixed-cost cover." -> Board-set buffer: c.1.5 months of total fixed-cost cover.
B16: 3. REVENUE - FORECAST WEEKLY RUN-RATES (gross of discounts)
B17: Physical store - gross sales per week | C17: 20300 | D17: SGD/wk
B18: E-commerce - gross sales per week | C18: 24500 | D18: SGD/wk | E18: Ahead of the 6-month average: e-commerce is growing.
B19: Events / pop-ups - gross sales per event week | C19: 24000 | D19: SGD/wk | E19: Applied only in weeks with a scheduled event.
B20: Consignment - gross sales per week (at partner retail) | C20: 7850 | D20: SGD/wk
B22: 4. DISCOUNTS, RETURNS AND GROSS MARGIN
B23: Store - discounts and returns | C23: 0.06 | D23: % of gross
B24: E-commerce - discounts and returns | C24: 0.12 | D24: % of gross | E24: Higher: size-driven online returns.
B25: Events - discounts and returns | C25: 0.03 | D25: % of gross
B26: Consignment - discounts and returns | C26: 0 | D26: % of gross | E26: Partner sells at full retail.
B28: Store - gross margin | C28: 0.58 | D28: % of net
B29: E-commerce - gross margin | C29: 0.6 | D29: % of net
B30: Events - gross margin | C30: 0.64 | D30: % of net | E30: Curated, full-price sell-through.
B31: Consignment - product gross margin (before commission) | C31: 0.6 | D31: % of net
B33: 5. VARIABLE CHANNEL COSTS (move with sales)
B34: Store - merchant / payment fees | C34: 0.018 | D34: % of net
B35: E-commerce - payment gateway and platform transaction fees | C35: 0.029 | D35: % of net
B36: Events - merchant / payment fees | C36: 0.019 | D36: % of net
B37: Store - variable / casual labour | C37: 0.03 | D37: % of net | E37: Weekend and peak-hour cover above base roster.
B38: Store - other direct costs (packaging, consumables) | C38: 0.008 | D38: % of net
B39: E-commerce - fulfilment and shipping, net of customer recovery | C39: 0.065 | D39: % of net
B40: E-commerce - digital marketing | C40: 0.09 | D40: % of net | E40: Performance media; scales with revenue.
B41: Events - event costs (space, fixtures, transport, crew) | C41: 0.18 | D41: % of net
B42: Consignment - partner commission | C42: 0.3 | D42: % of net | E42: Deducted by the partner before remittance.
B43: Consignment - handling and logistics | C43: 0.015 | D43: % of net
B45: 6. STORE DIRECT FIXED COSTS (monthly)
B46: Store rent | C46: 22000 | D46: SGD/mth | E46: Flagship lease; next break option at the end of Q1 2027.
B47: Store base payroll (manager + 2 full-time) | C47: 18500 | D47: SGD/mth
B48: Store utilities and service charge | C48: 2600 | D48: SGD/mth
B49: Store POS and store software | C49: 450 | D49: SGD/mth
...

Sheet Controls
B2: ATELIER NORTH PTE. LTD. | H2: SGD · synthetic data
B3: Model controls · every check must pass before the pack is issued | H3: Back to Dashboard
B5: MODEL STATUS | D5: =IF(COUNTIF(H8:H42,"FAIL")=0,"PASS","REVIEW REQUIRED") -> PASS | E5: ="("&COUNTIF(H8:H42,"PASS")&" of "&COUNTA($C$8:$C$42)&" controls passing)" -> (35 of 35 controls passing)
B6: Tolerances: S$0.50 on value reconciliations (rounding only), 0.001 on count and flag checks.
B7: Category | C7: Control · what it proves | D7: Expected | E7: Actual | F7: Variance | G7: Tolerance | H7: Result
B8: CASH INTEGRITY | C8: 1. Cash roll-forward: opening cash + receipts - outflows = closing cash, every week | D8: 0 | E8: =SUMPRODUCT(ABS('13W Cash Flow'!D10:P10+'13W Cash Flow'!D18:P18-'13W Cash Flow'!D36:P36-'13W Cash Flow'!D40:P40)) -> 1.4551915e-10 | F8: =E8-D8 -> 1.4551915e-10 | G8: 0.5 | H8: =IF(ABS(F8)<=G8,"PASS","FAIL") -> PASS
C9: 2. Cash continuity: each week's opening cash equals the prior week's closing cash | D9: 0 | E9: =SUMPRODUCT(ABS('13W Cash Flow'!E10:P10-'13W Cash Flow'!D40:O40)) -> 0 | F9: =E9-D9 -> 0 | G9: 0.5 | H9: =IF(ABS(F9)<=G9,"PASS","FAIL") -> PASS
C10: 3. Week 1 opening cash agrees to the opening balance on Assumptions | D10: 0 | E10: ='13W Cash Flow'!$D$10-Assumptions!$C$13 -> 0 | F10: =E10-D10 -> 0 | G10: 0.5 | H10: =IF(ABS(F10)<=G10,"PASS","FAIL") -> PASS
C11: 4. Total cash receipts equals the sum of the individual receipt lines | D11: 0 | E11: ='13W Cash Flow'!$Q$18-SUM('13W Cash Flow'!$Q$13:$Q$17) -> 0 | F11: =E11-D11 -> 0 | G11: 0.5 | H11: =IF(ABS(F11)<=G11,"PASS","FAIL") -> PASS
C12: 5. Total cash outflows equals the sum of the individual outflow lines | D12: 0 | E12: ='13W Cash Flow'!$Q$36-SUM('13W Cash Flow'!$Q$21:$Q$35) -> 0 | F12: =E12-D12 -> 0 | G12: 0.5 | H12: =IF(ABS(F12)<=G12,"PASS","FAIL") -> PASS
C13: 6. Minimum cash threshold applied consistently across all 13 weeks | D13: 0 | E13: =SUMPRODUCT(ABS('13W Cash Flow'!D41:P41-Assumptions!$C$14)) -> 0 | F13: =E13-D13 -> 0 | G13: 0.5 | H13: =IF(ABS(F13)<=G13,"PASS","FAIL") -> PASS
C14: 7. Forecast net sales equals the sum of the four channel sales lines | D14: 0 | E14: ='13W Cash Flow'!$Q$77-SUM('13W Cash Flow'!$Q$73:$Q$76) -> 0 | F14: =E14-D14 -> 0 | G14: 0.5 | H14: =IF(ABS(F14)<=G14,"PASS","FAIL") -> PASS
C15: 8. Every scheduled AW26 purchase payment falls inside the 13-week window | D15: 0 | E15: ='13W Cash Flow'!$Q$88-Assumptions!$C$120 -> 0 | F15: =E15-D15 -> 0 | G15: 0.5 | H15: =IF(ABS(F15)<=G15,"PASS","FAIL") -> PASS
C16: 9. Payment completeness: every configured payment date is captured exactly once (see the coverage test on the 13W Cash Flow tab) | D16: 0 | E16: =SUMPRODUCT(ABS('13W Cash Flow'!$D$101:$I$101)) -> 0 | F16: =E16-D16 -> 0 | G16: 0.001 | H16: =IF(ABS(F16)<=G16,"PASS","FAIL") -> PASS
B17: CHANNEL P&L | C17: 10. Channel P&L: total net revenue equals the sum of the four channels | D17: 0 | E17: ='Channel Profitability'!$H$8-SUM('Channel Profitability'!$D$8:$G$8) -> 0 | F17: =E17-D17 -> 0 | G17: 0.5 | H17: =IF(ABS(F17)<=G17,"PASS","FAIL") -> PASS
